[2024-07-08T02:36:52.638+0000] {task_context_logger.py:104} ERROR - Executor reports task instance <TaskInstance: Final.craw_data manual__2024-07-08T02:33:35.925175+00:00 [queued]> finished (failed) although the task says it's queued. (Info: None) Was the task killed externally?
