[2024-07-07T08:51:46.212+0000] {task_context_logger.py:104} ERROR - Executor reports task instance <TaskInstance: final.starting manual__2024-07-07T08:51:32.730872+00:00 [queued]> finished (failed) although the task says it's queued. (Info: None) Was the task killed externally?
