[2024-07-07T06:34:11.636+0000] {task_context_logger.py:104} ERROR - Executor reports task instance <TaskInstance: Final_exam.starting scheduled__2024-07-07T06:32:00+00:00 [queued]> finished (failed) although the task says it's queued. (Info: None) Was the task killed externally?
