[2024-07-08T02:37:58.033+0000] {task_context_logger.py:104} ERROR - Executor reports task instance <TaskInstance: Final.craw_data scheduled__2024-07-08T02:31:24.918646+00:00 [queued]> finished (failed) although the task says it's queued. (Info: None) Was the task killed externally?
