[2024-07-08T02:45:57.049+0000] {task_context_logger.py:104} ERROR - Executor reports task instance <TaskInstance: Final.starting manual__2024-07-08T02:45:56.090590+00:00 [queued]> finished (failed) although the task says it's queued. (Info: None) Was the task killed externally?
