[2024-07-07T13:55:42.593+0000] {task_context_logger.py:104} ERROR - Executor reports task instance <TaskInstance: Final.starting scheduled__2024-07-07T13:53:11.984499+00:00 [queued]> finished (failed) although the task says it's queued. (Info: None) Was the task killed externally?
