[2024-07-07T13:29:26.820+0000] {local_task_job_runner.py:120} INFO - ::group::Pre task execution logs
[2024-07-07T13:29:26.845+0000] {taskinstance.py:2076} INFO - Dependencies all met for dep_context=non-requeueable deps ti=<TaskInstance: Final.cap_quyen_task manual__2024-07-07T13:29:18.431719+00:00 [queued]>
[2024-07-07T13:29:26.853+0000] {taskinstance.py:2076} INFO - Dependencies all met for dep_context=requeueable deps ti=<TaskInstance: Final.cap_quyen_task manual__2024-07-07T13:29:18.431719+00:00 [queued]>
[2024-07-07T13:29:26.855+0000] {taskinstance.py:2306} INFO - Starting attempt 1 of 2
[2024-07-07T13:29:26.873+0000] {taskinstance.py:2330} INFO - Executing <Task(BashOperator): cap_quyen_task> on 2024-07-07 13:29:18.431719+00:00
[2024-07-07T13:29:26.881+0000] {warnings.py:110} WARNING - /home/***/.local/lib/python3.12/site-packages/***/task/task_runner/standard_task_runner.py:61: DeprecationWarning: This process (pid=68) is multi-threaded, use of fork() may lead to deadlocks in the child.
  pid = os.fork()

[2024-07-07T13:29:26.884+0000] {standard_task_runner.py:63} INFO - Started process 70 to run task
[2024-07-07T13:29:26.884+0000] {standard_task_runner.py:90} INFO - Running: ['***', 'tasks', 'run', 'Final', 'cap_quyen_task', 'manual__2024-07-07T13:29:18.431719+00:00', '--job-id', '184', '--raw', '--subdir', 'DAGS_FOLDER/dag_test.py', '--cfg-path', '/tmp/tmpv63opc5h']
[2024-07-07T13:29:26.885+0000] {standard_task_runner.py:91} INFO - Job 184: Subtask cap_quyen_task
[2024-07-07T13:29:26.951+0000] {task_command.py:426} INFO - Running <TaskInstance: Final.cap_quyen_task manual__2024-07-07T13:29:18.431719+00:00 [running]> on host d24963bb3847
[2024-07-07T13:29:27.053+0000] {taskinstance.py:2648} INFO - Exporting env vars: AIRFLOW_CTX_DAG_EMAIL='ha20040204@gmail.com' AIRFLOW_CTX_DAG_OWNER='HA' AIRFLOW_CTX_DAG_ID='Final' AIRFLOW_CTX_TASK_ID='cap_quyen_task' AIRFLOW_CTX_EXECUTION_DATE='2024-07-07T13:29:18.431719+00:00' AIRFLOW_CTX_TRY_NUMBER='1' AIRFLOW_CTX_DAG_RUN_ID='manual__2024-07-07T13:29:18.431719+00:00'
[2024-07-07T13:29:27.055+0000] {taskinstance.py:430} INFO - ::endgroup::
[2024-07-07T13:29:27.057+0000] {subprocess.py:63} INFO - Tmp dir root location: /tmp
[2024-07-07T13:29:27.058+0000] {subprocess.py:75} INFO - Running command: ['/usr/bin/bash', '-c', 'chown ***:*** /opt/***/share_data']
[2024-07-07T13:29:27.071+0000] {subprocess.py:86} INFO - Output:
[2024-07-07T13:29:27.075+0000] {subprocess.py:93} INFO - chown: invalid group: ‘***:***’
[2024-07-07T13:29:27.076+0000] {subprocess.py:97} INFO - Command exited with return code 1
[2024-07-07T13:29:27.078+0000] {taskinstance.py:441} INFO - ::group::Post task execution logs
[2024-07-07T13:29:27.092+0000] {taskinstance.py:2905} ERROR - Task failed with exception
Traceback (most recent call last):
  File "/home/airflow/.local/lib/python3.12/site-packages/airflow/models/taskinstance.py", line 465, in _execute_task
    result = _execute_callable(context=context, **execute_callable_kwargs)
             ^^^^^^^^^^^^^^^^^^^^^^^^^^^^^^^^^^^^^^^^^^^^^^^^^^^^^^^^^^^^^
  File "/home/airflow/.local/lib/python3.12/site-packages/airflow/models/taskinstance.py", line 432, in _execute_callable
    return execute_callable(context=context, **execute_callable_kwargs)
           ^^^^^^^^^^^^^^^^^^^^^^^^^^^^^^^^^^^^^^^^^^^^^^^^^^^^^^^^^^^^
  File "/home/airflow/.local/lib/python3.12/site-packages/airflow/models/baseoperator.py", line 400, in wrapper
    return func(self, *args, **kwargs)
           ^^^^^^^^^^^^^^^^^^^^^^^^^^^
  File "/home/airflow/.local/lib/python3.12/site-packages/airflow/operators/bash.py", line 243, in execute
    raise AirflowException(
airflow.exceptions.AirflowException: Bash command failed. The command returned a non-zero exit code 1.
[2024-07-07T13:29:27.097+0000] {taskinstance.py:1206} INFO - Marking task as UP_FOR_RETRY. dag_id=Final, task_id=cap_quyen_task, run_id=manual__2024-07-07T13:29:18.431719+00:00, execution_date=20240707T132918, start_date=20240707T132926, end_date=20240707T132927
[2024-07-07T13:29:27.119+0000] {warnings.py:110} WARNING - /home/***/.local/lib/python3.12/site-packages/***/utils/email.py:154: RemovedInAirflow3Warning: Fetching SMTP credentials from configuration variables will be deprecated in a future release. Please set credentials using a connection instead.
  send_mime_email(e_from=mail_from, e_to=recipients, mime_msg=msg, conn_id=conn_id, dryrun=dryrun)

[2024-07-07T13:29:27.120+0000] {configuration.py:1050} WARNING - section/key [smtp/smtp_user] not found in config
[2024-07-07T13:29:27.121+0000] {email.py:271} INFO - Email alerting: attempt 1
[2024-07-07T13:29:27.138+0000] {configuration.py:1050} WARNING - section/key [smtp/smtp_user] not found in config
[2024-07-07T13:29:27.139+0000] {email.py:271} INFO - Email alerting: attempt 1
[2024-07-07T13:29:27.140+0000] {taskinstance.py:879} ERROR - Failed to send email to: ['ha20040204@gmail.com']
Traceback (most recent call last):
  File "/home/airflow/.local/lib/python3.12/site-packages/airflow/models/taskinstance.py", line 2479, in _run_raw_task
    self._execute_task_with_callbacks(context, test_mode, session=session)
  File "/home/airflow/.local/lib/python3.12/site-packages/airflow/models/taskinstance.py", line 2676, in _execute_task_with_callbacks
    result = self._execute_task(context, task_orig)
             ^^^^^^^^^^^^^^^^^^^^^^^^^^^^^^^^^^^^^^
  File "/home/airflow/.local/lib/python3.12/site-packages/airflow/models/taskinstance.py", line 2701, in _execute_task
    return _execute_task(self, context, task_orig)
           ^^^^^^^^^^^^^^^^^^^^^^^^^^^^^^^^^^^^^^^
  File "/home/airflow/.local/lib/python3.12/site-packages/airflow/models/taskinstance.py", line 465, in _execute_task
    result = _execute_callable(context=context, **execute_callable_kwargs)
             ^^^^^^^^^^^^^^^^^^^^^^^^^^^^^^^^^^^^^^^^^^^^^^^^^^^^^^^^^^^^^
  File "/home/airflow/.local/lib/python3.12/site-packages/airflow/models/taskinstance.py", line 432, in _execute_callable
    return execute_callable(context=context, **execute_callable_kwargs)
           ^^^^^^^^^^^^^^^^^^^^^^^^^^^^^^^^^^^^^^^^^^^^^^^^^^^^^^^^^^^^
  File "/home/airflow/.local/lib/python3.12/site-packages/airflow/models/baseoperator.py", line 400, in wrapper
    return func(self, *args, **kwargs)
           ^^^^^^^^^^^^^^^^^^^^^^^^^^^
  File "/home/airflow/.local/lib/python3.12/site-packages/airflow/operators/bash.py", line 243, in execute
    raise AirflowException(
airflow.exceptions.AirflowException: Bash command failed. The command returned a non-zero exit code 1.

During handling of the above exception, another exception occurred:

Traceback (most recent call last):
  File "/home/airflow/.local/lib/python3.12/site-packages/airflow/models/taskinstance.py", line 1063, in _email_alert
    send_email(task.email, subject, html_content)
  File "/home/airflow/.local/lib/python3.12/site-packages/airflow/utils/email.py", line 80, in send_email
    return backend(
           ^^^^^^^^
  File "/home/airflow/.local/lib/python3.12/site-packages/airflow/utils/email.py", line 154, in send_email_smtp
    send_mime_email(e_from=mail_from, e_to=recipients, mime_msg=msg, conn_id=conn_id, dryrun=dryrun)
  File "/home/airflow/.local/lib/python3.12/site-packages/airflow/utils/email.py", line 273, in send_mime_email
    smtp_conn = _get_smtp_connection(smtp_host, smtp_port, smtp_timeout, smtp_ssl)
                ^^^^^^^^^^^^^^^^^^^^^^^^^^^^^^^^^^^^^^^^^^^^^^^^^^^^^^^^^^^^^^^^^^
  File "/home/airflow/.local/lib/python3.12/site-packages/airflow/utils/email.py", line 317, in _get_smtp_connection
    return smtplib.SMTP(host=host, port=port, timeout=timeout)
           ^^^^^^^^^^^^^^^^^^^^^^^^^^^^^^^^^^^^^^^^^^^^^^^^^^^
  File "/usr/local/lib/python3.12/smtplib.py", line 255, in __init__
    (code, msg) = self.connect(host, port)
                  ^^^^^^^^^^^^^^^^^^^^^^^^
  File "/usr/local/lib/python3.12/smtplib.py", line 341, in connect
    self.sock = self._get_socket(host, port, self.timeout)
                ^^^^^^^^^^^^^^^^^^^^^^^^^^^^^^^^^^^^^^^^^^
  File "/usr/local/lib/python3.12/smtplib.py", line 312, in _get_socket
    return socket.create_connection((host, port), timeout,
           ^^^^^^^^^^^^^^^^^^^^^^^^^^^^^^^^^^^^^^^^^^^^^^^
  File "/usr/local/lib/python3.12/socket.py", line 852, in create_connection
    raise exceptions[0]
  File "/usr/local/lib/python3.12/socket.py", line 837, in create_connection
    sock.connect(sa)
ConnectionRefusedError: [Errno 111] Connection refused

During handling of the above exception, another exception occurred:

Traceback (most recent call last):
  File "/home/airflow/.local/lib/python3.12/site-packages/airflow/models/taskinstance.py", line 877, in _handle_failure
    task_instance.email_alert(error, failure_context["task"])
  File "/home/airflow/.local/lib/python3.12/site-packages/airflow/models/taskinstance.py", line 3163, in email_alert
    _email_alert(task_instance=self, exception=exception, task=task)
  File "/home/airflow/.local/lib/python3.12/site-packages/airflow/models/taskinstance.py", line 1065, in _email_alert
    send_email(task.email, subject, html_content_err)
  File "/home/airflow/.local/lib/python3.12/site-packages/airflow/utils/email.py", line 80, in send_email
    return backend(
           ^^^^^^^^
  File "/home/airflow/.local/lib/python3.12/site-packages/airflow/utils/email.py", line 154, in send_email_smtp
    send_mime_email(e_from=mail_from, e_to=recipients, mime_msg=msg, conn_id=conn_id, dryrun=dryrun)
  File "/home/airflow/.local/lib/python3.12/site-packages/airflow/utils/email.py", line 273, in send_mime_email
    smtp_conn = _get_smtp_connection(smtp_host, smtp_port, smtp_timeout, smtp_ssl)
                ^^^^^^^^^^^^^^^^^^^^^^^^^^^^^^^^^^^^^^^^^^^^^^^^^^^^^^^^^^^^^^^^^^
  File "/home/airflow/.local/lib/python3.12/site-packages/airflow/utils/email.py", line 317, in _get_smtp_connection
    return smtplib.SMTP(host=host, port=port, timeout=timeout)
           ^^^^^^^^^^^^^^^^^^^^^^^^^^^^^^^^^^^^^^^^^^^^^^^^^^^
  File "/usr/local/lib/python3.12/smtplib.py", line 255, in __init__
    (code, msg) = self.connect(host, port)
                  ^^^^^^^^^^^^^^^^^^^^^^^^
  File "/usr/local/lib/python3.12/smtplib.py", line 341, in connect
    self.sock = self._get_socket(host, port, self.timeout)
                ^^^^^^^^^^^^^^^^^^^^^^^^^^^^^^^^^^^^^^^^^^
  File "/usr/local/lib/python3.12/smtplib.py", line 312, in _get_socket
    return socket.create_connection((host, port), timeout,
           ^^^^^^^^^^^^^^^^^^^^^^^^^^^^^^^^^^^^^^^^^^^^^^^
  File "/usr/local/lib/python3.12/socket.py", line 852, in create_connection
    raise exceptions[0]
  File "/usr/local/lib/python3.12/socket.py", line 837, in create_connection
    sock.connect(sa)
ConnectionRefusedError: [Errno 111] Connection refused
[2024-07-07T13:29:27.173+0000] {standard_task_runner.py:110} ERROR - Failed to execute job 184 for task cap_quyen_task (Bash command failed. The command returned a non-zero exit code 1.; 70)
[2024-07-07T13:29:27.219+0000] {local_task_job_runner.py:240} INFO - Task exited with return code 1
[2024-07-07T13:29:27.287+0000] {taskinstance.py:3498} INFO - 0 downstream tasks scheduled from follow-on schedule check
[2024-07-07T13:29:27.305+0000] {local_task_job_runner.py:222} INFO - ::endgroup::
